Traceback (most recent call last):
  File "/opt/miniconda3/envs/book/lib/python3.12/site-packages/jupyter_cache/executors/utils.py", line 58, in single_nb_execution
    executenb(
  File "/opt/miniconda3/envs/book/lib/python3.12/site-packages/nbclient/client.py", line 1319, in execute
    return NotebookClient(nb=nb, resources=resources, km=km, **kwargs).execute()
           ^^^^^^^^^^^^^^^^^^^^^^^^^^^^^^^^^^^^^^^^^^^^^^^^^^^^^^^^^^^^^^^^^^^^^
  File "/opt/miniconda3/envs/book/lib/python3.12/site-packages/jupyter_core/utils/__init__.py", line 165, in wrapped
    return loop.run_until_complete(inner)
           ^^^^^^^^^^^^^^^^^^^^^^^^^^^^^^
  File "/opt/miniconda3/envs/book/lib/python3.12/asyncio/base_events.py", line 686, in run_until_complete
    return future.result()
           ^^^^^^^^^^^^^^^
  File "/opt/miniconda3/envs/book/lib/python3.12/site-packages/nbclient/client.py", line 709, in async_execute
    await self.async_execute_cell(
  File "/opt/miniconda3/envs/book/lib/python3.12/site-packages/nbclient/client.py", line 1062, in async_execute_cell
    await self._check_raise_for_error(cell, cell_index, exec_reply)
  File "/opt/miniconda3/envs/book/lib/python3.12/site-packages/nbclient/client.py", line 918, in _check_raise_for_error
    raise CellExecutionError.from_cell_and_msg(cell, exec_reply_content)
nbclient.exceptions.CellExecutionError: An error occurred while executing the following cell:
------------------
# Send request
response = requests.get(url)

# Convert to DataFrame
df = pd.DataFrame(response.json()[1:], columns=data[0])
df["B01003_001E"] = pd.to_numeric(df["B01003_001E"])
df.head()
------------------


[0;31m---------------------------------------------------------------------------[0m
[0;31mNameError[0m                                 Traceback (most recent call last)
Cell [0;32mIn[11], line 5[0m
[1;32m      2[0m response [38;5;241m=[39m requests[38;5;241m.[39mget(url)
[1;32m      4[0m [38;5;66;03m# Convert to DataFrame[39;00m
[0;32m----> 5[0m df [38;5;241m=[39m pd[38;5;241m.[39mDataFrame(response[38;5;241m.[39mjson()[[38;5;241m1[39m:], columns[38;5;241m=[39m[43mdata[49m[[38;5;241m0[39m])
[1;32m      6[0m df[[38;5;124m"[39m[38;5;124mB01003_001E[39m[38;5;124m"[39m] [38;5;241m=[39m pd[38;5;241m.[39mto_numeric(df[[38;5;124m"[39m[38;5;124mB01003_001E[39m[38;5;124m"[39m])
[1;32m      7[0m df[38;5;241m.[39mhead()

[0;31mNameError[0m: name 'data' is not defined

